<mujocoinclude>
    <body name="Object" pos="-0.00 0.0 0.035" user="1001 0 2003 27 0 0 0.06 0 0">
        <inertial pos="0 0 0" mass="0.179594" diaginertia="8.80012e-05 8.80012e-05 8.80012e-05" />
        <joint name="OBJTx" pos="0 0 0" axis="1 0 0" type="slide" limited="false" damping="0" />
        <joint name="OBJTy" pos="0 0 0" axis="0 1 0" type="slide" limited="false" damping="0" />
        <joint name="OBJTz" pos="0 0 0" axis="0 0 1" type="slide" limited="false" damping="0" />
        <joint name="OBJRx" pos="0 0 0" axis="1 0 0" limited="false" damping="0" />
        <joint name="OBJRy" pos="0 0 0" axis="0 1 0" limited="false" damping="0" />
        <joint name="OBJRz" pos="0 0 0" axis="0 0 1" limited="false" damping="0" />
        <geom name="object" size="0.035" condim="4" material="MatWoodB" />
    </body>
</mujocoinclude>