<?xml version="1.0" ?>
<!-- =================================================================================== -->
<!-- |    This document was autogenerated by xacro from leap_moveit/config/leap.urdf.xacro | -->
<!-- |    EDITING THIS FILE BY HAND IS NOT RECOMMENDED                                 | -->
<!-- =================================================================================== -->
<robot name="leap">
  <link name="palm_lower">
    <visual>
      <origin rpy="0 -0 0" xyz="-0.020095249652862544332 0.025757756134899473244 -0.034722403578460216134"/>
      <geometry>
        <mesh filename="package://leap_description/assets/leap_hand/palm_lower.stl"/>
      </geometry>
      <material name="palm_lower_material">
        <color rgba="1 1 1 1.0"/>
      </material>
    </visual>
    <collision>
      <origin rpy="0 -0 0" xyz="-0.020095249652862544332 0.025757756134899473244 -0.034722403578460216134"/>
      <geometry>
        <mesh filename="package://leap_description/assets/leap_hand/palm_lower_collision.stl"/>
      </geometry>
    </collision>
    <inertial>
      <origin rpy="0 0 0" xyz="0 0 0"/>
      <mass value="0.237"/>
      <inertia ixx="0.000354094" ixy="-0.000001193" ixz="-0.000002445" iyy="0.000260915" iyz="-0.000002905" izz="0.000529257"/>
    </inertial>
  </link>
  <link name="index_proximal_phalanx_1">
    <visual>
      <origin rpy="0 0 0" xyz="0.008407 0.007766 0.014657"/>
      <geometry>
        <mesh filename="package://leap_description/assets/leap_hand/proximal_phalanx_1.stl"/>
      </geometry>
      <material name="proximal_phalanx_1_material">
        <color rgba="0.0 0 0 1.0"/>
      </material>
    </visual>
    <collision>
      <origin rpy="0 0 0" xyz="0.008407 0.007766 0.014657"/>
      <geometry>
        <mesh filename="package://leap_description/assets/leap_hand/proximal_phalanx_1_collision.stl"/>
      </geometry>
    </collision>
    <collision>
      <origin rpy="0 0 0" xyz="-0.0 0.007 0.014"/>
      <geometry>
        <box size="0.0225 0.03 0.035"/>
      </geometry>
    </collision>
    <inertial>
      <origin rpy="0 0 0" xyz="0 0 0"/>
      <mass value="0.044"/>
      <inertia ixx="0.000011499" ixy="0.000003049" ixz="0.000000121" iyy="0.000007796" iyz="0.000000112" izz="0.000014759"/>
    </inertial>
  </link>
  <link name="index_proximal_phalanx_2">
    <visual>
      <origin rpy="-1.570796326794896558 -1.570796326794896336 0" xyz="0.009643 0.0003 0.000784"/>
      <geometry>
        <mesh filename="package://leap_description/assets/leap_hand/proximal_phalanx_2.stl"/>
      </geometry>
      <material name="proximal_phalanx_2_material">
        <color rgba="0.0 0 0 1.0"/>
      </material>
    </visual>
    <collision>
      <origin rpy="-1.570796326794896558 -1.570796326794896336 0" xyz="0.009643 0.0003 0.000784"/>
      <geometry>
        <mesh filename="package://leap_description/assets/leap_hand/proximal_phalanx_2_collision.stl"/>
      </geometry>
    </collision>
    <inertial>
      <origin rpy="0 0 0" xyz="0 0 0"/>
      <mass value="0.032"/>
      <inertia ixx="0.000004798" ixy="0.000000012" ixz="0.000000004" iyy="0.000002862" iyz="0.000000011" izz="0.000004234"/>
    </inertial>
  </link>
  <link name="index_middle_phalanx">
    <visual>
      <origin rpy="-3.141592653589793116 0 0" xyz="0.021133 -0.008432 0.009785"/>
      <geometry>
        <mesh filename="package://leap_description/assets/leap_hand/middle_phalanx.stl"/>
      </geometry>
      <material name="middle_phalanx_material">
        <color rgba="0.0 0 0 1.0"/>
      </material>
    </visual>
    <collision>
      <origin rpy="-3.141592653589793116 0 0" xyz="0.021133 -0.008432 0.009785"/>
      <geometry>
        <mesh filename="package://leap_description/assets/leap_hand/middle_phalanx_collision.stl"/>
      </geometry>
    </collision>
    <inertial>
      <origin rpy="0 0 0" xyz="0 0 0"/>
      <mass value="0.037"/>
      <inertia ixx="0.000005542" ixy="-0.000000607" ixz="-0.000000017" iyy="0.000005727" iyz="-0.000000023" izz="0.000006682"/>
    </inertial>
  </link>
  <link name="index_distal_phalanx">
    <visual>
      <origin rpy="3.141592653589793116 0 0" xyz="0.0132864 -0.006114 0.0145"/>
      <geometry>
        <mesh filename="package://leap_description/assets/leap_hand/distal_phalanx.stl"/>
      </geometry>
      <material name="distal_phalanx_material">
        <color rgba="1 1 1 1.0"/>
      </material>
    </visual>
    <collision>
      <origin rpy="3.141592653589793116 0 0" xyz="0.013286 -0.006114 0.0145"/>
      <geometry>
        <mesh filename="package://leap_description/assets/leap_hand/distal_phalanx_collision.stl"/>
      </geometry>
    </collision>
    <inertial>
      <origin rpy="0 0 0" xyz="0 0 0"/>
      <mass value="0.016"/>
      <inertia ixx="0.000003368" ixy="0.000000115" ixz="0" iyy="0.000001556" iyz="0" izz="0.000002863"/>
    </inertial>
  </link>
  <joint name="index_pip_flex_joint" type="revolute">
    <origin rpy="1.5707963267948950037 1.5707963267948945596 0" xyz="-0.007095249652862546 0.023057756134899472 -0.01872240357846022"/>
    <parent link="palm_lower"/>
    <child link="index_proximal_phalanx_1"/>
    <axis xyz="0 0 -1"/>
    <limit acceleration="20.0" effort="0.95" lower="-0.314" upper="2.23" velocity="8.48"/>
    <joint_properties friction="0.0"/>
  </joint>
  <joint name="index_pip_abb_joint" type="revolute">
    <origin rpy="-1.570796326794896558 0 1.5707963267948943376" xyz="-0.0122 0.0381 0.0145"/>
    <parent link="index_proximal_phalanx_1"/>
    <child link="index_proximal_phalanx_2"/>
    <axis xyz="0 0 -1"/>
    <limit acceleration="20.0" effort="0.95" lower="-1.047" upper="1.047" velocity="8.48"/>
    <joint_properties friction="0.0"/>
  </joint>
  <joint name="index_mcp_joint" type="revolute">
    <origin rpy="1.5707963267948958919 -1.570796326794896336 0" xyz="0.015 0.0143 -0.013"/>
    <parent link="index_proximal_phalanx_2"/>
    <child link="index_middle_phalanx"/>
    <axis xyz="0 0 -1"/>
    <limit acceleration="20.0" effort="0.95" lower="-0.506" upper="1.885" velocity="8.48"/>
    <joint_properties friction="0.0"/>
  </joint>
  <joint name="index_dip_joint" type="revolute">
    <origin rpy="0 0 0" xyz="0 -0.0361 0.0002"/>
    <parent link="index_middle_phalanx"/>
    <child link="index_distal_phalanx"/>
    <axis xyz="0 0 -1"/>
    <limit acceleration="20.0" effort="0.95" lower="-0.366" upper="2.042" velocity="8.48"/>
    <joint_properties friction="0.0"/>
  </joint>
  <link name="middle_proximal_phalanx_1">
    <visual>
      <origin rpy="0 0 0" xyz="0.008407 0.007766 0.014657"/>
      <geometry>
        <mesh filename="package://leap_description/assets/leap_hand/proximal_phalanx_1.stl"/>
      </geometry>
      <material name="proximal_phalanx_1_material">
        <color rgba="0.0 0 0 1.0"/>
      </material>
    </visual>
    <collision>
      <origin rpy="0 0 0" xyz="0.008407 0.007766 0.014657"/>
      <geometry>
        <mesh filename="package://leap_description/assets/leap_hand/proximal_phalanx_1_collision.stl"/>
      </geometry>
    </collision>
    <collision>
      <origin rpy="0 0 0" xyz="-0.0 0.007 0.014"/>
      <geometry>
        <box size="0.0225 0.03 0.035"/>
      </geometry>
    </collision>
    <inertial>
      <origin rpy="0 0 0" xyz="0 0 0"/>
      <mass value="0.044"/>
      <inertia ixx="0.000011499" ixy="0.000003049" ixz="0.000000121" iyy="0.000007796" iyz="0.000000112" izz="0.000014759"/>
    </inertial>
  </link>
  <link name="middle_proximal_phalanx_2">
    <visual>
      <origin rpy="-1.570796326794896558 -1.570796326794896336 0" xyz="0.009643 0.0003 0.000784"/>
      <geometry>
        <mesh filename="package://leap_description/assets/leap_hand/proximal_phalanx_2.stl"/>
      </geometry>
      <material name="proximal_phalanx_2_material">
        <color rgba="0.0 0 0 1.0"/>
      </material>
    </visual>
    <collision>
      <origin rpy="-1.570796326794896558 -1.570796326794896336 0" xyz="0.009643 0.0003 0.000784"/>
      <geometry>
        <mesh filename="package://leap_description/assets/leap_hand/proximal_phalanx_2_collision.stl"/>
      </geometry>
    </collision>
    <inertial>
      <origin rpy="0 0 0" xyz="0 0 0"/>
      <mass value="0.032"/>
      <inertia ixx="0.000004798" ixy="0.000000012" ixz="0.000000004" iyy="0.000002862" iyz="0.000000011" izz="0.000004234"/>
    </inertial>
  </link>
  <link name="middle_middle_phalanx">
    <visual>
      <origin rpy="-3.141592653589793116 0 0" xyz="0.021133 -0.008432 0.009785"/>
      <geometry>
        <mesh filename="package://leap_description/assets/leap_hand/middle_phalanx.stl"/>
      </geometry>
      <material name="middle_phalanx_material">
        <color rgba="0.0 0 0 1.0"/>
      </material>
    </visual>
    <collision>
      <origin rpy="-3.141592653589793116 0 0" xyz="0.021133 -0.008432 0.009785"/>
      <geometry>
        <mesh filename="package://leap_description/assets/leap_hand/middle_phalanx_collision.stl"/>
      </geometry>
    </collision>
    <inertial>
      <origin rpy="0 0 0" xyz="0 0 0"/>
      <mass value="0.037"/>
      <inertia ixx="0.000005542" ixy="-0.000000607" ixz="-0.000000017" iyy="0.000005727" iyz="-0.000000023" izz="0.000006682"/>
    </inertial>
  </link>
  <link name="middle_distal_phalanx">
    <visual>
      <origin rpy="3.141592653589793116 0 0" xyz="0.0132864 -0.006114 0.0145"/>
      <geometry>
        <mesh filename="package://leap_description/assets/leap_hand/distal_phalanx.stl"/>
      </geometry>
      <material name="distal_phalanx_material">
        <color rgba="1 1 1 1.0"/>
      </material>
    </visual>
    <collision>
      <origin rpy="3.141592653589793116 0 0" xyz="0.013286 -0.006114 0.0145"/>
      <geometry>
        <mesh filename="package://leap_description/assets/leap_hand/distal_phalanx_collision.stl"/>
      </geometry>
    </collision>
    <inertial>
      <origin rpy="0 0 0" xyz="0 0 0"/>
      <mass value="0.016"/>
      <inertia ixx="0.000003368" ixy="0.000000115" ixz="0" iyy="0.000001556" iyz="0" izz="0.000002863"/>
    </inertial>
  </link>
  <joint name="middle_pip_flex_joint" type="revolute">
    <origin rpy="1.5707963267948950037 1.5707963267948945596 0" xyz="-0.007095249652862546 -0.022392243865100525 -0.01872240357846022"/>
    <parent link="palm_lower"/>
    <child link="middle_proximal_phalanx_1"/>
    <axis xyz="0 0 -1"/>
    <limit acceleration="20.0" effort="0.95" lower="-0.314" upper="2.23" velocity="8.48"/>
    <joint_properties friction="0.0"/>
  </joint>
  <joint name="middle_pip_abb_joint" type="revolute">
    <origin rpy="-1.570796326794896558 0 1.5707963267948943376" xyz="-0.0122 0.0381 0.0145"/>
    <parent link="middle_proximal_phalanx_1"/>
    <child link="middle_proximal_phalanx_2"/>
    <axis xyz="0 0 -1"/>
    <limit acceleration="20.0" effort="0.95" lower="-1.047" upper="1.047" velocity="8.48"/>
    <joint_properties friction="0.0"/>
  </joint>
  <joint name="middle_mcp_joint" type="revolute">
    <origin rpy="1.5707963267948958919 -1.570796326794896336 0" xyz="0.015 0.0143 -0.013"/>
    <parent link="middle_proximal_phalanx_2"/>
    <child link="middle_middle_phalanx"/>
    <axis xyz="0 0 -1"/>
    <limit acceleration="20.0" effort="0.95" lower="-0.506" upper="1.885" velocity="8.48"/>
    <joint_properties friction="0.0"/>
  </joint>
  <joint name="middle_dip_joint" type="revolute">
    <origin rpy="0 0 0" xyz="0 -0.0361 0.0002"/>
    <parent link="middle_middle_phalanx"/>
    <child link="middle_distal_phalanx"/>
    <axis xyz="0 0 -1"/>
    <limit acceleration="20.0" effort="0.95" lower="-0.366" upper="2.042" velocity="8.48"/>
    <joint_properties friction="0.0"/>
  </joint>
  <link name="ring_proximal_phalanx_1">
    <visual>
      <origin rpy="0 0 0" xyz="0.008407 0.007766 0.014657"/>
      <geometry>
        <mesh filename="package://leap_description/assets/leap_hand/proximal_phalanx_1.stl"/>
      </geometry>
      <material name="proximal_phalanx_1_material">
        <color rgba="0.0 0 0 1.0"/>
      </material>
    </visual>
    <collision>
      <origin rpy="0 0 0" xyz="0.008407 0.007766 0.014657"/>
      <geometry>
        <mesh filename="package://leap_description/assets/leap_hand/proximal_phalanx_1_collision.stl"/>
      </geometry>
    </collision>
    <collision>
      <origin rpy="0 0 0" xyz="-0.0 0.007 0.014"/>
      <geometry>
        <box size="0.0225 0.03 0.035"/>
      </geometry>
    </collision>
    <inertial>
      <origin rpy="0 0 0" xyz="0 0 0"/>
      <mass value="0.044"/>
      <inertia ixx="0.000011499" ixy="0.000003049" ixz="0.000000121" iyy="0.000007796" iyz="0.000000112" izz="0.000014759"/>
    </inertial>
  </link>
  <link name="ring_proximal_phalanx_2">
    <visual>
      <origin rpy="-1.570796326794896558 -1.570796326794896336 0" xyz="0.009643 0.0003 0.000784"/>
      <geometry>
        <mesh filename="package://leap_description/assets/leap_hand/proximal_phalanx_2.stl"/>
      </geometry>
      <material name="proximal_phalanx_2_material">
        <color rgba="0.0 0 0 1.0"/>
      </material>
    </visual>
    <collision>
      <origin rpy="-1.570796326794896558 -1.570796326794896336 0" xyz="0.009643 0.0003 0.000784"/>
      <geometry>
        <mesh filename="package://leap_description/assets/leap_hand/proximal_phalanx_2_collision.stl"/>
      </geometry>
    </collision>
    <inertial>
      <origin rpy="0 0 0" xyz="0 0 0"/>
      <mass value="0.032"/>
      <inertia ixx="0.000004798" ixy="0.000000012" ixz="0.000000004" iyy="0.000002862" iyz="0.000000011" izz="0.000004234"/>
    </inertial>
  </link>
  <link name="ring_middle_phalanx">
    <visual>
      <origin rpy="-3.141592653589793116 0 0" xyz="0.021133 -0.008432 0.009785"/>
      <geometry>
        <mesh filename="package://leap_description/assets/leap_hand/middle_phalanx.stl"/>
      </geometry>
      <material name="middle_phalanx_material">
        <color rgba="0.0 0 0 1.0"/>
      </material>
    </visual>
    <collision>
      <origin rpy="-3.141592653589793116 0 0" xyz="0.021133 -0.008432 0.009785"/>
      <geometry>
        <mesh filename="package://leap_description/assets/leap_hand/middle_phalanx_collision.stl"/>
      </geometry>
    </collision>
    <inertial>
      <origin rpy="0 0 0" xyz="0 0 0"/>
      <mass value="0.037"/>
      <inertia ixx="0.000005542" ixy="-0.000000607" ixz="-0.000000017" iyy="0.000005727" iyz="-0.000000023" izz="0.000006682"/>
    </inertial>
  </link>
  <link name="ring_distal_phalanx">
    <visual>
      <origin rpy="3.141592653589793116 0 0" xyz="0.0132864 -0.006114 0.0145"/>
      <geometry>
        <mesh filename="package://leap_description/assets/leap_hand/distal_phalanx.stl"/>
      </geometry>
      <material name="distal_phalanx_material">
        <color rgba="1 1 1 1.0"/>
      </material>
    </visual>
    <collision>
      <origin rpy="3.141592653589793116 0 0" xyz="0.013286 -0.006114 0.0145"/>
      <geometry>
        <mesh filename="package://leap_description/assets/leap_hand/distal_phalanx_collision.stl"/>
      </geometry>
    </collision>
    <inertial>
      <origin rpy="0 0 0" xyz="0 0 0"/>
      <mass value="0.016"/>
      <inertia ixx="0.000003368" ixy="0.000000115" ixz="0" iyy="0.000001556" iyz="0" izz="0.000002863"/>
    </inertial>
  </link>
  <joint name="ring_pip_flex_joint" type="revolute">
    <origin rpy="1.5707963267948950037 1.5707963267948945596 0" xyz="-0.007095249652862546 -0.06784224386510052 -0.01872240357846022"/>
    <parent link="palm_lower"/>
    <child link="ring_proximal_phalanx_1"/>
    <axis xyz="0 0 -1"/>
    <limit acceleration="20.0" effort="0.95" lower="-0.314" upper="2.23" velocity="8.48"/>
    <joint_properties friction="0.0"/>
  </joint>
  <joint name="ring_pip_abb_joint" type="revolute">
    <origin rpy="-1.570796326794896558 0 1.5707963267948943376" xyz="-0.0122 0.0381 0.0145"/>
    <parent link="ring_proximal_phalanx_1"/>
    <child link="ring_proximal_phalanx_2"/>
    <axis xyz="0 0 -1"/>
    <limit acceleration="20.0" effort="0.95" lower="-1.047" upper="1.047" velocity="8.48"/>
    <joint_properties friction="0.0"/>
  </joint>
  <joint name="ring_mcp_joint" type="revolute">
    <origin rpy="1.5707963267948958919 -1.570796326794896336 0" xyz="0.015 0.0143 -0.013"/>
    <parent link="ring_proximal_phalanx_2"/>
    <child link="ring_middle_phalanx"/>
    <axis xyz="0 0 -1"/>
    <limit acceleration="20.0" effort="0.95" lower="-0.506" upper="1.885" velocity="8.48"/>
    <joint_properties friction="0.0"/>
  </joint>
  <joint name="ring_dip_joint" type="revolute">
    <origin rpy="0 0 0" xyz="0 -0.0361 0.0002"/>
    <parent link="ring_middle_phalanx"/>
    <child link="ring_distal_phalanx"/>
    <axis xyz="0 0 -1"/>
    <limit acceleration="20.0" effort="0.95" lower="-0.366" upper="2.042" velocity="8.48"/>
    <joint_properties friction="0.0"/>
  </joint>
  <link name="thumb_semi_palm_1">
    <visual>
      <origin rpy="-1.570796326794896558 -1.570796326794896336 0" xyz="-0.005356 0.0003 0.000784"/>
      <geometry>
        <mesh filename="package://leap_description/assets/leap_hand/proximal_phalanx_2.stl"/>
      </geometry>
      <material name="thumb_semi_palm_2_material">
        <color rgba="0 0 0 1.0"/>
      </material>
    </visual>
    <collision>
      <origin rpy="-1.570796326794896558 -1.570796326794896336 0" xyz="-0.005356 0.0003 0.000784"/>
      <geometry>
        <mesh filename="package://leap_description/assets/leap_hand/proximal_phalanx_2_collision.stl"/>
      </geometry>
    </collision>
    <inertial>
      <origin rpy="0 0 0" xyz="0 0 0"/>
      <mass value="0.032"/>
      <inertia ixx="0.000004798" ixy="0.000000012" ixz="0.000000004" iyy="0.000002862" iyz="0.000000011" izz="0.000004234"/>
    </inertial>
  </link>
  <link name="thumb_semi_palm_2">
    <visual>
      <origin rpy="1.570796326794896558 0 0" xyz="0.011962 0 -0.0158526"/>
      <geometry>
        <mesh filename="package://leap_description/assets/leap_hand/thumb_semi_palm.stl"/>
      </geometry>
      <material name="thumb_semi_palm_2_material">
        <color rgba="0 0 0 1.0"/>
      </material>
    </visual>
    <collision>
      <origin rpy="1.570796326794896558 0 0" xyz="0.011962 0 -0.015853"/>
      <geometry>
        <mesh filename="package://leap_description/assets/leap_hand/thumb_semi_palm_collision.stl"/>
      </geometry>
    </collision>
    <inertial>
      <origin rpy="0 0 0" xyz="0 0 0"/>
      <mass value="0.003"/>
      <inertia ixx="0.000000593" ixy="0" ixz="0" iyy="0.000000549" iyz="0" izz="0.000000224"/>
    </inertial>
  </link>
  <link name="thumb_middle_phalanx">
    <visual>
      <origin rpy="0 0 0" xyz="0.0439687 0.057953 -0.008629"/>
      <geometry>
        <mesh filename="package://leap_description/assets/leap_hand/thumb_middle_phalanx.stl"/>
      </geometry>
      <material name="thumb_middle_phalanx_material">
        <color rgba="0 0 0 1.0"/>
      </material>
    </visual>
    <collision>
      <origin rpy="0 0 0" xyz="0.0439687 0.057953 -0.008629"/>
      <geometry>
        <mesh filename="package://leap_description/assets/leap_hand/thumb_middle_phalanx_collision.stl"/>
      </geometry>
    </collision>
    <inertial>
      <origin rpy="0 0 0" xyz="0 0 0"/>
      <mass value="0.038"/>
      <inertia ixx="0.000008474" ixy="0.000000241" ixz="0.000000026" iyy="0.000003841" iyz="0.000000025" izz="0.000007679"/>
    </inertial>
  </link>
  <link name="thumb_distal_phalanx">
    <visual>
      <origin rpy="0 0 0" xyz="0.06256 0.07846 0.048993"/>
      <geometry>
        <mesh filename="package://leap_description/assets/leap_hand/thumb_distal_phalanx.stl"/>
      </geometry>
      <material name="thumb_distal_phalanx_material">
        <color rgba="1 1 1 1.0"/>
      </material>
    </visual>
    <collision>
      <origin rpy="0 0 0" xyz="0.06256 0.07846 0.048993"/>
      <geometry>
        <mesh filename="package://leap_description/assets/leap_hand/thumb_distal_phalanx_collision.stl"/>
      </geometry>
    </collision>
    <inertial>
      <origin rpy="0 0 0" xyz="0 0 0"/>
      <mass value="0.049"/>
      <inertia ixx="0.000020372" ixy="-0.000000489" ixz="-0.00000003" iyy="0.000004336" iyz="-0.000000097" izz="0.000019845"/>
    </inertial>
  </link>
  <joint name="thumb_cmc_abb_joint" type="revolute">
    <origin rpy="0 1.5707963267948956698 0" xyz="-0.069395 -0.001242 -0.0216224"/>
    <parent link="palm_lower"/>
    <child link="thumb_semi_palm_1"/>
    <axis xyz="0 0 -1"/>
    <limit acceleration="20.0" effort="0.95" lower="-0.349" upper="2.094" velocity="8.48"/>
    <joint_properties friction="0.0"/>
  </joint>
  <joint name="thumb_cmc_flex_joint" type="revolute">
    <origin rpy="1.5707963267948958919 1.5707963267948958919 0" xyz="0 0.0143 -0.013"/>
    <parent link="thumb_semi_palm_1"/>
    <child link="thumb_semi_palm_2"/>
    <axis xyz="0 0 -1"/>
    <limit acceleration="20.0" effort="0.95" lower="-2.47" upper="2.443" velocity="8.48"/>
    <joint_properties friction="0.0"/>
  </joint>
  <joint name="thumb_mcp_joint" type="revolute">
    <origin rpy="-1.570796326794896558 0 0" xyz="0 0.0145 -0.017"/>
    <parent link="thumb_semi_palm_2"/>
    <child link="thumb_middle_phalanx"/>
    <axis xyz="0 0 -1"/>
    <limit acceleration="20.0" effort="0.95" lower="-1.20" upper="1.90" velocity="8.48"/>
    <joint_properties friction="0.0"/>
  </joint>
  <joint name="thumb_ip_joint" type="revolute">
    <origin rpy="0 0 3.141592653589793116" xyz="0 0.0466 0.0002"/>
    <parent link="thumb_middle_phalanx"/>
    <child link="thumb_distal_phalanx"/>
    <axis xyz="0 0 -1"/>
    <limit acceleration="20.0" effort="0.95" lower="-1.34" upper="1.88" velocity="8.48"/>
    <joint_properties friction="0.0"/>
  </joint>
  <!-- Import control_xacro -->
  <ros2_control name="FakeSystem" type="system">
    <hardware>
      <plugin>mock_components/GenericSystem</plugin>
    </hardware>
    <joint name="index_pip_flex_joint">
      <command_interface name="position"/>
      <state_interface name="position">
        <param name="initial_value">0</param>
      </state_interface>
      <state_interface name="velocity"/>
    </joint>
    <joint name="index_pip_abb_joint">
      <command_interface name="position"/>
      <state_interface name="position">
        <param name="initial_value">0</param>
      </state_interface>
      <state_interface name="velocity"/>
    </joint>
    <joint name="index_mcp_joint">
      <command_interface name="position"/>
      <state_interface name="position">
        <param name="initial_value">0</param>
      </state_interface>
      <state_interface name="velocity"/>
    </joint>
    <joint name="index_dip_joint">
      <command_interface name="position"/>
      <state_interface name="position">
        <param name="initial_value">0</param>
      </state_interface>
      <state_interface name="velocity"/>
    </joint>
    <joint name="middle_pip_flex_joint">
      <command_interface name="position"/>
      <state_interface name="position">
        <param name="initial_value">0</param>
      </state_interface>
      <state_interface name="velocity"/>
    </joint>
    <joint name="middle_pip_abb_joint">
      <command_interface name="position"/>
      <state_interface name="position">
        <param name="initial_value">0</param>
      </state_interface>
      <state_interface name="velocity"/>
    </joint>
    <joint name="middle_mcp_joint">
      <command_interface name="position"/>
      <state_interface name="position">
        <param name="initial_value">0</param>
      </state_interface>
      <state_interface name="velocity"/>
    </joint>
    <joint name="middle_dip_joint">
      <command_interface name="position"/>
      <state_interface name="position">
        <param name="initial_value">0</param>
      </state_interface>
      <state_interface name="velocity"/>
    </joint>
    <joint name="ring_pip_flex_joint">
      <command_interface name="position"/>
      <state_interface name="position">
        <param name="initial_value">0</param>
      </state_interface>
      <state_interface name="velocity"/>
    </joint>
    <joint name="ring_pip_abb_joint">
      <command_interface name="position"/>
      <state_interface name="position">
        <param name="initial_value">0</param>
      </state_interface>
      <state_interface name="velocity"/>
    </joint>
    <joint name="ring_mcp_joint">
      <command_interface name="position"/>
      <state_interface name="position">
        <param name="initial_value">0</param>
      </state_interface>
      <state_interface name="velocity"/>
    </joint>
    <joint name="ring_dip_joint">
      <command_interface name="position"/>
      <state_interface name="position">
        <param name="initial_value">0</param>
      </state_interface>
      <state_interface name="velocity"/>
    </joint>
    <joint name="thumb_cmc_abb_joint">
      <command_interface name="position"/>
      <state_interface name="position">
        <param name="initial_value">0</param>
      </state_interface>
      <state_interface name="velocity"/>
    </joint>
    <joint name="thumb_cmc_flex_joint">
      <command_interface name="position"/>
      <state_interface name="position">
        <param name="initial_value">0</param>
      </state_interface>
      <state_interface name="velocity"/>
    </joint>
    <joint name="thumb_mcp_joint">
      <command_interface name="position"/>
      <state_interface name="position">
        <param name="initial_value">0</param>
      </state_interface>
      <state_interface name="velocity"/>
    </joint>
    <joint name="thumb_ip_joint">
      <command_interface name="position"/>
      <state_interface name="position">
        <param name="initial_value">0</param>
      </state_interface>
      <state_interface name="velocity"/>
    </joint>
  </ros2_control>
</robot>
