<mujocoinclude>
    <body name="Object" pos="0.00 0.0 0.035" >
        <!-- <geom type="mesh" mesh="ycb_mesh" rgba="0.2 0.2 0.2 1" contype="0" conaffinity="0"/> -->
        <!-- <geom name="sphere" type="mesh" mass="0.034" mesh="ycb_mesh" material="ycb_material"/> -->

        <geom material="material_0.001" mesh="textured_centered" class="visual"/>

        <geom name="object_0" mass="0.00213" mesh="object_0" rgba="0.2622529240531396 0.35274006661842183 0.030120110609602402 1" class="collision"/>
        <geom name="object_1" mass="0.00213" mesh="object_1" rgba="0.7745836813651212 0.04942534407369137 0.9869863654712593 1" class="collision"/>
        <geom name="object_2" mass="0.00213" mesh="object_2" rgba="0.6534036928827824 0.4435123278138048 0.7841540970928286 1" class="collision"/>
        <geom name="object_3" mass="0.00213" mesh="object_3" rgba="0.14383604384434656 0.6609407810211276 0.3622154957398047 1" class="collision"/>
        <geom name="object_4" mass="0.00213" mesh="object_4" rgba="0.2622529240531396 0.35274006661842183 0.030120110609602402 1" class="collision"/>
        <geom name="object_5" mass="0.00213" mesh="object_5" rgba="0.7745836813651212 0.04942534407369137 0.9869863654712593 1" class="collision"/>
        <geom name="object_6" mass="0.00213" mesh="object_6" rgba="0.6534036928827824 0.4435123278138048 0.7841540970928286 1" class="collision"/>
        <geom name="object_7" mass="0.00213" mesh="object_7" rgba="0.14383604384434656 0.6609407810211276 0.3622154957398047 1" class="collision"/>
        <geom name="object_8" mass="0.00213" mesh="object_8" rgba="0.2622529240531396 0.35274006661842183 0.030120110609602402 1" class="collision"/>
        <geom name="object_9" mass="0.00213" mesh="object_9" rgba="0.7745836813651212 0.04942534407369137 0.9869863654712593 1" class="collision"/>
        <geom name="object_10" mass="0.00213" mesh="object_10" rgba="0.6534036928827824 0.4435123278138048 0.7841540970928286 1" class="collision"/> 
        <geom name="object_11" mass="0.00213" mesh="object_11" rgba="0.14383604384434656 0.6609407810211276 0.3622154957398047 1" class="collision"/>
        <geom name="object_12" mass="0.00213" mesh="object_12" rgba="0.2622529240531396 0.35274006661842183 0.030120110609602402 1" class="collision"/>
        <geom name="object_13" mass="0.00213" mesh="object_13" rgba="0.7745836813651212 0.04942534407369137 0.9869863654712593 1" class="collision"/>
        <geom name="object_14" mass="0.00213" mesh="object_14" rgba="0.6534036928827824 0.4435123278138048 0.7841540970928286 1" class="collision"/>
        <geom name="object_15" mass="0.00213" mesh="object_15" rgba="0.14383604384434656 0.6609407810211276 0.3622154957398047 1" class="collision"/>
    
        <!-- <geom mesh="object_0" rgba="0.2622529240531396 0.35274006661842183 0.030120110609602402 1" class="visual"/> -->
        <!-- <geom mesh="object_1" rgba="0.7745836813651212 0.04942534407369137 0.9869863654712593 1" class="visual"/> -->
        <!-- <geom mesh="object_2" rgba="0.6534036928827824 0.4435123278138048 0.7841540970928286 1" class="visual"/> -->
        <!-- <geom mesh="object_3" rgba="0.14383604384434656 0.6609407810211276 0.3622154957398047 1" class="visual"/> -->
        <!-- <geom mesh="object_4" rgba="0.2622529240531396 0.35274006661842183 0.030120110609602402 1" class="visual"/> -->
        <!-- <geom mesh="object_5" rgba="0.7745836813651212 0.04942534407369137 0.9869863654712593 1" class="visual"/> -->
        <!-- <geom mesh="object_6" rgba="0.6534036928827824 0.4435123278138048 0.7841540970928286 1" class="visual"/> -->
        <!-- <geom mesh="object_7" rgba="0.14383604384434656 0.6609407810211276 0.3622154957398047 1" class="visual"/> -->
        <!-- <geom mesh="object_8" rgba="0.2622529240531396 0.35274006661842183 0.030120110609602402 1" class="visual"/> -->
        <!-- <geom mesh="object_9" rgba="0.7745836813651212 0.04942534407369137 0.9869863654712593 1" class="visual"/> -->
        <!-- <geom mesh="object_10" rgba="0.6534036928827824 0.4435123278138048 0.7841540970928286 1" class="visual"/>  -->
        <!-- <geom mesh="object_11" rgba="0.14383604384434656 0.6609407810211276 0.3622154957398047 1" class="visual"/> -->
        <!-- <geom mesh="object_12" rgba="0.2622529240531396 0.35274006661842183 0.030120110609602402 1" class="visual"/> -->
        <!-- <geom mesh="object_13" rgba="0.7745836813651212 0.04942534407369137 0.9869863654712593 1" class="visual"/> -->
        <!-- <geom mesh="object_14" rgba="0.6534036928827824 0.4435123278138048 0.7841540970928286 1" class="visual"/> -->
        <!-- <geom mesh="object_15" rgba="0.14383604384434656 0.6609407810211276 0.3622154957398047 1" class="visual"/> -->



        <!-- <inertial pos="0 0 0" mass="0.205" diaginertia="8.80012e-05 8.80012e-05 8.80012e-05" /> -->
        <joint name="YCBTx" pos="0 0 0" axis="1 0 0" type="slide" limited="false" damping="0" />
        <joint name="YCBTy" pos="0 0 0" axis="0 1 0" type="slide" limited="false" damping="0" />
        <joint name="YCBTz" pos="0 0 0" axis="0 0 1" type="slide" limited="false" damping="0" />
        <joint name="YCBRx" pos="0 0 0" axis="1 0 0" limited="false" damping="0" />
        <joint name="YCBRy" pos="0 0 0" axis="0 1 0" limited="false" damping="0" />
        <joint name="YCBRz" pos="0 0 0" axis="0 0 1" limited="false" damping="0" />
    </body>
</mujocoinclude>