<mujocoinclude>
            <!-- <compiler mesh="exact"/> -->
            <body name="Object" pos="0 0 0.035">
                <geom material="material_0.001" mesh="textured_centered" class="visual"/>
                <geom name="object_0" mass="0.0019" margin="0.0025" mesh="object_0" rgba="0.2622529240531396 0.35274006661842183 0.030120110609602402 1" class="collision"/>
                <geom name="object_1" mass="0.0019" margin="0.0025" mesh="object_1" rgba="0.7745836813651212 0.04942534407369137 0.9869863654712593 1" class="collision"/>
                <geom name="object_2" mass="0.0019" margin="0.0025" mesh="object_2" rgba="0.6534036928827824 0.4435123278138048 0.7841540970928286 1" class="collision"/>
                <geom name="object_3" mass="0.0019" margin="0.0025" mesh="object_3" rgba="0.14383604384434656 0.6609407810211276 0.3622154957398047 1" class="collision"/>
                <geom name="object_4" mass="0.0019" margin="0.0025" mesh="object_4" rgba="0.7893550973888946 0.9551543412767667 0.3713242922447202 1" class="collision"/>
                <geom name="object_5" mass="0.0019" margin="0.0025" mesh="object_5" rgba="0.9969406479899974 0.738421106397313 0.06819649656582649 1" class="collision"/>
                <geom name="object_6" mass="0.0019" margin="0.0025" mesh="object_6" rgba="0.09886608147520182 0.5847756605720145 0.6413534038165082 1" class="collision"/>
                <geom name="object_7" mass="0.0019" margin="0.0025" mesh="object_7" rgba="0.8524222187307497 0.8202813724525853 0.7987111310713944 1" class="collision"/>
                <geom name="object_8" mass="0.0019" margin="0.0025" mesh="object_8" rgba="0.435427722617693 0.35793038320556214 0.9931095820590345 1" class="collision"/>
                <geom name="object_9" mass="0.0019" margin="0.0025" mesh="object_9" rgba="0.7901704822196078 0.7273873029625257 0.07028290037834184 1" class="collision"/>
                <geom name="object_10" mass="0.0019" margin="0.0025" mesh="object_10" rgba="0.15403629251796858 0.045578537121582774 0.7021328838053558 1" class="collision"/>
                <geom name="object_11" mass="0.0019" margin="0.0025" mesh="object_11" rgba="0.3713795557938595 0.5041253797138958 0.14969135851464088 1" class="collision"/>
                <geom name="object_12" mass="0.0019" margin="0.0025" mesh="object_12" rgba="0.9269055079450834 0.003668956389055733 0.5828104264482676 1" class="collision"/>
                <geom name="object_13" mass="0.0019" margin="0.0025" mesh="object_13" rgba="0.7814280622653128 0.6930730135044523 0.5705509996081206 1" class="collision"/>
                <geom name="object_14" mass="0.0019" margin="0.0025" mesh="object_14" rgba="0.6819357159179177 0.10648064434685467 0.8158992813815045 1" class="collision"/>
                <geom name="object_15" mass="0.0019" margin="0.0025" mesh="object_15" rgba="0.8914902168048838 0.8514218625472354 0.5545547179913195 1" class="collision"/>
                <geom name="object_16" mass="0.0019" margin="0.0025" mesh="object_16" rgba="0.11643344809478162 0.38732190173480263 0.6320387634830404 1" class="collision"/>
                <geom name="object_17" mass="0.0019" margin="0.0025" mesh="object_17" rgba="0.8189895571493561 0.9827677188852326 0.8987570664148185 1" class="collision"/>
                <geom name="object_18" mass="0.0019" margin="0.0025" mesh="object_18" rgba="0.9632489794048172 0.4569699157275422 0.46331055662602927 1" class="collision"/>
                <geom name="object_19" mass="0.0019" margin="0.0025" mesh="object_19" rgba="0.9105205407783997 0.20928914957692535 0.023950001161551215 1" class="collision"/>
                <geom name="object_20" mass="0.0019" margin="0.0025" mesh="object_20" rgba="0.1876993342515766 0.5722456109878179 0.2131176769211639 1" class="collision"/>
                <geom name="object_21" mass="0.0019" margin="0.0025" mesh="object_21" rgba="0.47272349808000846 0.3846532066364493 0.4287737233805715 1" class="collision"/>
                <geom name="object_22" mass="0.0019" margin="0.0025" mesh="object_22" rgba="0.2622529240531396 0.35274006661842183 0.030120110609602402 1" class="collision"/>
                <geom name="object_23" mass="0.0019" margin="0.0025" mesh="object_23" rgba="0.7745836813651212 0.04942534407369137 0.9869863654712593 1" class="collision"/>
                <geom name="object_24" mass="0.0019" margin="0.0025" mesh="object_24" rgba="0.6534036928827824 0.4435123278138048 0.7841540970928286 1" class="collision"/>
                <geom name="object_25" mass="0.0019" margin="0.0025" mesh="object_25" rgba="0.14383604384434656 0.6609407810211276 0.3622154957398047 1" class="collision"/>
                <geom name="object_26" mass="0.0019" margin="0.0025" mesh="object_26" rgba="0.7893550973888946 0.9551543412767667 0.3713242922447202 1" class="collision"/>
                <geom name="object_27" mass="0.0019" margin="0.0025" mesh="object_27" rgba="0.9969406479899974 0.738421106397313 0.06819649656582649 1" class="collision"/>
                <geom name="object_28" mass="0.0019" margin="0.0025" mesh="object_28" rgba="0.09886608147520182 0.5847756605720145 0.6413534038165082 1" class="collision"/>
                <geom name="object_29" mass="0.0019" margin="0.0025" mesh="object_29" rgba="0.8524222187307497 0.8202813724525853 0.7987111310713944 1" class="collision"/>
                <geom name="object_30" mass="0.0019" margin="0.0025" mesh="object_30" rgba="0.435427722617693 0.35793038320556214 0.9931095820590345 1" class="collision"/>
                <geom name="object_31" mass="0.0019" margin="0.0025" mesh="object_31" rgba="0.7901704822196078 0.7273873029625257 0.07028290037834184 1" class="collision"/>
                <geom name="object_32" mass="0.0019" margin="0.0025" mesh="object_32" rgba="0.15403629251796858 0.045578537121582774 0.7021328838053558 1" class="collision"/>
                <geom name="object_33" mass="0.0019" margin="0.0025" mesh="object_33" rgba="0.3713795557938595 0.5041253797138958 0.14969135851464088 1" class="collision"/>
                <geom name="object_34" mass="0.0019" margin="0.0025" mesh="object_34" rgba="0.9269055079450834 0.003668956389055733 0.5828104264482676 1" class="collision"/>
                <geom name="object_35" mass="0.0019" margin="0.0025" mesh="object_35" rgba="0.7814280622653128 0.6930730135044523 0.5705509996081206 1" class="collision"/>
                <geom name="object_36" mass="0.0019" margin="0.0025" mesh="object_36" rgba="0.6819357159179177 0.10648064434685467 0.8158992813815045 1" class="collision"/>
                <geom name="object_37" mass="0.0019" margin="0.0025" mesh="object_37" rgba="0.8914902168048838 0.8514218625472354 0.5545547179913195 1" class="collision"/>
                <geom name="object_38" mass="0.0019" margin="0.0025" mesh="object_38" rgba="0.11643344809478162 0.38732190173480263 0.6320387634830404 1" class="collision"/>
                <geom name="object_39" mass="0.0019" margin="0.0025" mesh="object_39" rgba="0.8189895571493561 0.9827677188852326 0.8987570664148185 1" class="collision"/>
                <geom name="object_40" mass="0.0019" margin="0.0025" mesh="object_40" rgba="0.9632489794048172 0.4569699157275422 0.46331055662602927 1" class="collision"/>
                <geom name="object_41" mass="0.0019" margin="0.0025" mesh="object_41" rgba="0.9105205407783997 0.20928914957692535 0.023950001161551215 1" class="collision"/>
                <geom name="object_42" mass="0.0019" margin="0.0025" mesh="object_42" rgba="0.1876993342515766 0.5722456109878179 0.2131176769211639 1" class="collision"/>
                <geom name="object_43" mass="0.0019" margin="0.0025" mesh="object_43" rgba="0.47272349808000846 0.3846532066364493 0.4287737233805715 1" class="collision"/>
                <geom name="object_44" mass="0.0019" margin="0.0025" mesh="object_44" rgba="0.2622529240531396 0.35274006661842183 0.030120110609602402 1" class="collision"/>
                <geom name="object_45" mass="0.0019" margin="0.0025" mesh="object_45" rgba="0.7745836813651212 0.04942534407369137 0.9869863654712593 1" class="collision"/>
                <geom name="object_46" mass="0.0019" margin="0.0025" mesh="object_46" rgba="0.6534036928827824 0.4435123278138048 0.7841540970928286 1" class="collision"/>
                <geom name="object_47" mass="0.0019" margin="0.0025" mesh="object_47" rgba="0.14383604384434656 0.6609407810211276 0.3622154957398047 1" class="collision"/>
                <geom name="object_48" mass="0.0019" margin="0.0025" mesh="object_48" rgba="0.7893550973888946 0.9551543412767667 0.3713242922447202 1" class="collision"/>
                <geom name="object_49" mass="0.0019" margin="0.0025" mesh="object_49" rgba="0.9969406479899974 0.738421106397313 0.06819649656582649 1" class="collision"/>
                <geom name="object_50" mass="0.0019" margin="0.0025" mesh="object_50" rgba="0.09886608147520182 0.5847756605720145 0.6413534038165082 1" class="collision"/>
                <geom name="object_51" mass="0.0019" margin="0.0025" mesh="object_51" rgba="0.8524222187307497 0.8202813724525853 0.7987111310713944 1" class="collision"/>
                <geom name="object_52" mass="0.0019" margin="0.0025" mesh="object_52" rgba="0.435427722617693 0.35793038320556214 0.9931095820590345 1" class="collision"/>
                <geom name="object_53" mass="0.0019" margin="0.0025" mesh="object_53" rgba="0.7901704822196078 0.7273873029625257 0.07028290037834184 1" class="collision"/>
                <geom name="object_54" mass="0.0019" margin="0.0025" mesh="object_54" rgba="0.7901704822196078 0.7273873029625257 0.07028290037834184 1" class="collision"/>
                <geom name="object_55" mass="0.0019" margin="0.0025" mesh="object_55" rgba="0.7893550973888946 0.9551543412767667 0.3713242922447202 1" class="collision"/>
                <geom name="object_56" mass="0.0019" margin="0.0025" mesh="object_56" rgba="0.9969406479899974 0.738421106397313 0.06819649656582649 1" class="collision"/>
                <geom name="object_57" mass="0.0019" margin="0.0025" mesh="object_57" rgba="0.09886608147520182 0.5847756605720145 0.6413534038165082 1" class="collision"/>
                <geom name="object_58" mass="0.0019" margin="0.0025" mesh="object_58" rgba="0.8524222187307497 0.8202813724525853 0.7987111310713944 1" class="collision"/>
                <geom name="object_59" mass="0.0019" margin="0.0025" mesh="object_59" rgba="0.435427722617693 0.35793038320556214 0.9931095820590345 1" class="collision"/>
                <geom name="object_60" mass="0.0019" margin="0.0025" mesh="object_60" rgba="0.7901704822196078 0.7273873029625257 0.07028290037834184 1" class="collision"/>
                <geom name="object_61" mass="0.0019" margin="0.0025" mesh="object_61" rgba="0.15403629251796858 0.045578537121582774 0.7021328838053558 1" class="collision"/>
                <geom name="object_62" mass="0.0019" margin="0.0025" mesh="object_62" rgba="0.3713795557938595 0.5041253797138958 0.14969135851464088 1" class="collision"/>
                <geom name="object_63" mass="0.0019" margin="0.0025" mesh="object_63" rgba="0.9269055079450834 0.003668956389055733 0.5828104264482676 1" class="collision"/>
                <geom name="object_64" mass="0.0019" margin="0.0025" mesh="object_64" rgba="0.7814280622653128 0.6930730135044523 0.5705509996081206 1" class="collision"/>
                <geom name="object_65" mass="0.0019" margin="0.0025" mesh="object_65" rgba="0.6819357159179177 0.10648064434685467 0.8158992813815045 1" class="collision"/>
                <geom name="object_66" mass="0.0019" margin="0.0025" mesh="object_66" rgba="0.8914902168048838 0.8514218625472354 0.5545547179913195 1" class="collision"/>
                <geom name="object_67" mass="0.0019" margin="0.0025" mesh="object_67" rgba="0.11643344809478162 0.38732190173480263 0.6320387634830404 1" class="collision"/>
                <geom name="object_68" mass="0.0019" margin="0.0025" mesh="object_68" rgba="0.8189895571493561 0.9827677188852326 0.8987570664148185 1" class="collision"/>
                <geom name="object_69" mass="0.0019" margin="0.0025" mesh="object_69" rgba="0.9632489794048172 0.4569699157275422 0.46331055662602927 1" class="collision"/>
                <geom name="object_70" mass="0.0019" margin="0.0025" mesh="object_70" rgba="0.9105205407783997 0.20928914957692535 0.023950001161551215 1" class="collision"/>
                <geom name="object_71" mass="0.0019" margin="0.0025" mesh="object_71" rgba="0.1876993342515766 0.5722456109878179 0.2131176769211639 1" class="collision"/>
                <geom name="object_72" mass="0.0019" margin="0.0025" mesh="object_72" rgba="0.47272349808000846 0.3846532066364493 0.4287737233805715 1" class="collision"/>
                <geom name="object_73" mass="0.0019" margin="0.0025" mesh="object_73" rgba="0.2622529240531396 0.35274006661842183 0.030120110609602402 1" class="collision"/>
                <geom name="object_74" mass="0.0019" margin="0.0025" mesh="object_74" rgba="0.7745836813651212 0.04942534407369137 0.9869863654712593 1" class="collision"/>
                <geom name="object_75" mass="0.0019" margin="0.0025" mesh="object_75" rgba="0.6534036928827824 0.4435123278138048 0.7841540970928286 1" class="collision"/>
                <geom name="object_76" mass="0.0019" margin="0.0025" mesh="object_76" rgba="0.14383604384434656 0.6609407810211276 0.3622154957398047 1" class="collision"/>
                <geom name="object_77" mass="0.0019" margin="0.0025" mesh="object_77" rgba="0.7893550973888946 0.9551543412767667 0.3713242922447202 1" class="collision"/>
                <geom name="object_78" mass="0.0019" margin="0.0025" mesh="object_78" rgba="0.9969406479899974 0.738421106397313 0.06819649656582649 1" class="collision"/>
                <geom name="object_79" mass="0.0019" margin="0.0025" mesh="object_79" rgba="0.09886608147520182 0.5847756605720145 0.6413534038165082 1" class="collision"/>
                
                <!-- <geom mesh="object_0" margin="0.005" rgba="0.2622529240531396 0.35274006661842183 0.030120110609602402 1" class="visual"/> -->
                <!-- <geom mesh="object_1" margin="0.005" rgba="0.7745836813651212 0.04942534407369137 0.9869863654712593 1" class="visual"/> -->
                <!-- <geom mesh="object_2" margin="0.005" rgba="0.6534036928827824 0.4435123278138048 0.7841540970928286 1" class="visual"/> -->
                <!-- <geom mesh="object_3" margin="0.005" rgba="0.14383604384434656 0.6609407810211276 0.3622154957398047 1" class="visual"/> -->
                <!-- <geom mesh="object_4" margin="0.005" rgba="0.7893550973888946 0.9551543412767667 0.3713242922447202 1" class="visual"/> -->
                <!-- <geom mesh="object_5" margin="0.005" rgba="0.9969406479899974 0.738421106397313 0.06819649656582649 1" class="visual"/> -->
                <!-- <geom mesh="object_6" margin="0.005" rgba="0.09886608147520182 0.5847756605720145 0.6413534038165082 1" class="visual"/> -->
                <!-- <geom mesh="object_7" margin="0.005" rgba="0.8524222187307497 0.8202813724525853 0.7987111310713944 1" class="visual"/> -->
                <!-- <geom mesh="object_8" margin="0.005" rgba="0.435427722617693 0.35793038320556214 0.9931095820590345 1" class="visual"/> -->
                <!-- <geom mesh="object_9" margin="0.005" rgba="0.7901704822196078 0.7273873029625257 0.07028290037834184 1" class="visual"/> -->
                <!-- <geom mesh="object_10" margin="0.005" rgba="0.15403629251796858 0.045578537121582774 0.7021328838053558 1" class="visual"/> -->
                <!-- <geom mesh="object_11" margin="0.005" rgba="0.3713795557938595 0.5041253797138958 0.14969135851464088 1" class="visual"/> -->
                <!-- <geom mesh="object_12" margin="0.005" rgba="0.9269055079450834 0.003668956389055733 0.5828104264482676 1" class="visual"/> -->
                <!-- <geom mesh="object_13" margin="0.005" rgba="0.7814280622653128 0.6930730135044523 0.5705509996081206 1" class="visual"/> -->
                <!-- <geom mesh="object_14" margin="0.005" rgba="0.6819357159179177 0.10648064434685467 0.8158992813815045 1" class="visual"/> -->
                <!-- <geom mesh="object_15" margin="0.005" rgba="0.8914902168048838 0.8514218625472354 0.5545547179913195 1" class="visual"/> -->
                <!-- <geom mesh="object_16" margin="0.005" rgba="0.11643344809478162 0.38732190173480263 0.6320387634830404 1" class="visual"/> -->
                <!-- <geom mesh="object_17" margin="0.005" rgba="0.8189895571493561 0.9827677188852326 0.8987570664148185 1" class="visual"/> -->
                <!-- <geom mesh="object_18" margin="0.005" rgba="0.9632489794048172 0.4569699157275422 0.46331055662602927 1" class="visual"/> -->
                <!-- <geom mesh="object_19" margin="0.005" rgba="0.9105205407783997 0.20928914957692535 0.023950001161551215 1" class="visual"/> -->
                <!-- <geom mesh="object_20" margin="0.005" rgba="0.1876993342515766 0.5722456109878179 0.2131176769211639 1" class="visual"/> -->
                <!-- <geom mesh="object_21" margin="0.005" rgba="0.47272349808000846 0.3846532066364493 0.4287737233805715 1" class="visual"/> -->
                <!-- <geom mesh="object_22" margin="0.005" rgba="0.2622529240531396 0.35274006661842183 0.030120110609602402 1" class="visual"/> -->
                <!-- <geom mesh="object_23" margin="0.005" rgba="0.7745836813651212 0.04942534407369137 0.9869863654712593 1" class="visual"/> -->
                <!-- <geom mesh="object_24" margin="0.005" rgba="0.6534036928827824 0.4435123278138048 0.7841540970928286 1" class="visual"/> -->
                <!-- <geom mesh="object_25" margin="0.005" rgba="0.14383604384434656 0.6609407810211276 0.3622154957398047 1" class="visual"/> -->
                <!-- <geom mesh="object_26" margin="0.005" rgba="0.7893550973888946 0.9551543412767667 0.3713242922447202 1" class="visual"/> -->
                <!-- <geom mesh="object_27" margin="0.005" rgba="0.9969406479899974 0.738421106397313 0.06819649656582649 1" class="visual"/> -->
                <!-- <geom mesh="object_28" margin="0.005" rgba="0.09886608147520182 0.5847756605720145 0.6413534038165082 1" class="visual"/> -->
                <!-- <geom mesh="object_29" margin="0.005" rgba="0.8524222187307497 0.8202813724525853 0.7987111310713944 1" class="visual"/> -->
                <!-- <geom mesh="object_30" margin="0.005" rgba="0.435427722617693 0.35793038320556214 0.9931095820590345 1" class="visual"/> -->
                <!-- <geom mesh="object_31" margin="0.005" rgba="0.7901704822196078 0.7273873029625257 0.07028290037834184 1" class="visual"/> -->
                <!-- <geom mesh="object_32" margin="0.005" rgba="0.15403629251796858 0.045578537121582774 0.7021328838053558 1" class="visual"/> -->
                <!-- <geom mesh="object_33" margin="0.005" rgba="0.3713795557938595 0.5041253797138958 0.14969135851464088 1" class="visual"/> -->
                <!-- <geom mesh="object_34" margin="0.005" rgba="0.9269055079450834 0.003668956389055733 0.5828104264482676 1" class="visual"/> -->
                <!-- <geom mesh="object_35" margin="0.005" rgba="0.7814280622653128 0.6930730135044523 0.5705509996081206 1" class="visual"/> -->
                <!-- <geom mesh="object_36" margin="0.005" rgba="0.6819357159179177 0.10648064434685467 0.8158992813815045 1" class="visual"/> -->
                <!-- <geom mesh="object_37" margin="0.005" rgba="0.8914902168048838 0.8514218625472354 0.5545547179913195 1" class="visual"/> -->
                <!-- <geom mesh="object_38" margin="0.005" rgba="0.11643344809478162 0.38732190173480263 0.6320387634830404 1" class="visual"/> -->
                <!-- <geom mesh="object_39" margin="0.005" rgba="0.8189895571493561 0.9827677188852326 0.8987570664148185 1" class="visual"/> -->
                <!-- <geom mesh="object_40" margin="0.005" rgba="0.9632489794048172 0.4569699157275422 0.46331055662602927 1" class="visual"/> -->
                <!-- <geom mesh="object_41" margin="0.005" rgba="0.9105205407783997 0.20928914957692535 0.023950001161551215 1" class="visual"/> -->
                <!-- <geom mesh="object_42" margin="0.005" rgba="0.1876993342515766 0.5722456109878179 0.2131176769211639 1" class="visual"/> -->
                <!-- <geom mesh="object_43" margin="0.005" rgba="0.47272349808000846 0.3846532066364493 0.4287737233805715 1" class="visual"/> -->
                <!-- <geom mesh="object_44" margin="0.005" rgba="0.2622529240531396 0.35274006661842183 0.030120110609602402 1" class="visual"/> -->
                <!-- <geom mesh="object_45" margin="0.005" rgba="0.7745836813651212 0.04942534407369137 0.9869863654712593 1" class="visual"/> -->
                <!-- <geom mesh="object_46" margin="0.005" rgba="0.6534036928827824 0.4435123278138048 0.7841540970928286 1" class="visual"/> -->
                <!-- <geom mesh="object_47" margin="0.005" rgba="0.14383604384434656 0.6609407810211276 0.3622154957398047 1" class="visual"/> -->
                <!-- <geom mesh="object_48" margin="0.005" rgba="0.7893550973888946 0.9551543412767667 0.3713242922447202 1" class="visual"/> -->
                <!-- <geom mesh="object_49" margin="0.005" rgba="0.9969406479899974 0.738421106397313 0.06819649656582649 1" class="visual"/> -->
                <!-- <geom mesh="object_50" margin="0.005" rgba="0.09886608147520182 0.5847756605720145 0.6413534038165082 1" class="visual"/> -->
                <!-- <geom mesh="object_51" margin="0.005" rgba="0.8524222187307497 0.8202813724525853 0.7987111310713944 1" class="visual"/> -->
                <!-- <geom mesh="object_52" margin="0.005" rgba="0.435427722617693 0.35793038320556214 0.9931095820590345 1" class="visual"/> -->
                <!-- <geom mesh="object_53" margin="0.005" rgba="0.7901704822196078 0.7273873029625257 0.07028290037834184 1" class="visual"/> -->
                <!-- <geom mesh="object_54" margin="0.005" rgba="0.7901704822196078 0.7273873029625257 0.07028290037834184 1" class="visual"/> -->
                <!-- <geom mesh="object_55" margin="0.005" rgba="0.7893550973888946 0.9551543412767667 0.3713242922447202 1" class="visual"/> -->
                <!-- <geom mesh="object_56" margin="0.005" rgba="0.9969406479899974 0.738421106397313 0.06819649656582649 1" class="visual"/> -->
                <!-- <geom mesh="object_57" margin="0.005" rgba="0.09886608147520182 0.5847756605720145 0.6413534038165082 1" class="visual"/> -->
                <!-- <geom mesh="object_58" margin="0.005" rgba="0.8524222187307497 0.8202813724525853 0.7987111310713944 1" class="visual"/> -->
                <!-- <geom mesh="object_59" margin="0.005" rgba="0.435427722617693 0.35793038320556214 0.9931095820590345 1" class="visual"/> -->
                <!-- <geom mesh="object_60" margin="0.005" rgba="0.7901704822196078 0.7273873029625257 0.07028290037834184 1" class="visual"/> -->
                <!-- <geom mesh="object_61" margin="0.005" rgba="0.15403629251796858 0.045578537121582774 0.7021328838053558 1" class="visual"/> -->
                <!-- <geom mesh="object_62" margin="0.005" rgba="0.3713795557938595 0.5041253797138958 0.14969135851464088 1" class="visual"/> -->
                <!-- <geom mesh="object_63" margin="0.005" rgba="0.9269055079450834 0.003668956389055733 0.5828104264482676 1" class="visual"/> -->
                <!-- <geom mesh="object_64" margin="0.005" rgba="0.7814280622653128 0.6930730135044523 0.5705509996081206 1" class="visual"/> -->
                <!-- <geom mesh="object_65" margin="0.005" rgba="0.6819357159179177 0.10648064434685467 0.8158992813815045 1" class="visual"/> -->
                <!-- <geom mesh="object_66" margin="0.005" rgba="0.8914902168048838 0.8514218625472354 0.5545547179913195 1" class="visual"/> -->
                <!-- <geom mesh="object_67" margin="0.005" rgba="0.11643344809478162 0.38732190173480263 0.6320387634830404 1" class="visual"/> -->
                <!-- <geom mesh="object_68" margin="0.005" rgba="0.8189895571493561 0.9827677188852326 0.8987570664148185 1" class="visual"/> -->
                <!-- <geom mesh="object_69" margin="0.005" rgba="0.9632489794048172 0.4569699157275422 0.46331055662602927 1" class="visual"/> -->
                <!-- <geom mesh="object_70" margin="0.005" rgba="0.9105205407783997 0.20928914957692535 0.023950001161551215 1" class="visual"/> -->
                <!-- <geom mesh="object_71" margin="0.005" rgba="0.1876993342515766 0.5722456109878179 0.2131176769211639 1" class="visual"/> -->
                <!-- <geom mesh="object_72" margin="0.005" rgba="0.47272349808000846 0.3846532066364493 0.4287737233805715 1" class="visual"/> -->
                <!-- <geom mesh="object_73" margin="0.005" rgba="0.2622529240531396 0.35274006661842183 0.030120110609602402 1" class="visual"/> -->
                <!-- <geom mesh="object_74" margin="0.005" rgba="0.7745836813651212 0.04942534407369137 0.9869863654712593 1" class="visual"/> -->
                <!-- <geom mesh="object_75" margin="0.005" rgba="0.6534036928827824 0.4435123278138048 0.7841540970928286 1" class="visual"/> -->
                <!-- <geom mesh="object_76" margin="0.005" rgba="0.14383604384434656 0.6609407810211276 0.3622154957398047 1" class="visual"/> -->
                <!-- <geom mesh="object_77" margin="0.005" rgba="0.7893550973888946 0.9551543412767667 0.3713242922447202 1" class="visual"/> -->
                <!-- <geom mesh="object_78" margin="0.005" rgba="0.9969406479899974 0.738421106397313 0.06819649656582649 1" class="visual"/> -->
                <!-- <geom mesh="object_79" margin="0.005" rgba="0.09886608147520182 0.5847756605720145 0.6413534038165082 1" class="visual"/> -->
                
                <joint name="YCBTx" pos="0 0 0" axis="1 0 0" type="slide" limited="false" damping="0" />
                <joint name="YCBTy" pos="0 0 0" axis="0 1 0" type="slide" limited="false" damping="0" />
                <joint name="YCBTz" pos="0 0 0" axis="0 0 1" type="slide" limited="false" damping="0" />
                <joint name="YCBRx" pos="0 0 0" axis="1 0 0" limited="false" damping="0" />
                <joint name="YCBRy" pos="0 0 0" axis="0 1 0" limited="false" damping="0" />
                <joint name="YCBRz" pos="0 0 0" axis="0 0 1" limited="false" damping="0" />
            </body>
</mujocoinclude>